---
title: Promise 对象
categories:
tags:
  - javascript
---

## 什么是 promise 解决哪些问题的 （基于回调

1. 回调地狱 （代码不好维护，错误处理非常的麻烦，不能统一处理错误）
2. 多个请求的并发问题，（之前写的并发读取文件，自己定义定时器）

## 描述

Promise 对象用于表示一个异步操作的最终完成 (或失败), 及其结果值。 Promise 对象是一个代理对象（代理一个值），被代理的值在 Promise 对象创建时可能是未知的。它允许你为异步操作的成功和失败分别绑定相应的处理方法（handlers）。 这让异步方法可以像同步方法那样返回值，但并不是立即返回最终执行结果，而是一个能代表未来出现的结果的 promise 对象

一个 Promise 有以下几种状态:

- pending: 初始状态，既不是成功，也不是失败状态。
- fulfilled: 意味着操作成功完成。
- rejected: 意味着操作失败。

pending 状态的 Promise 对象可能会变为 fulfilled 状态并传递一个值给相应的状态处理方法，也可能变为失败状态（rejected）并传递失败信息。当其中任一种情况出现时，Promise 对象的 then 方法绑定的处理方法（handlers ）就会被调用（then 方法包含两个参数：onfulfilled 和 onrejected，它们都是 Function 类型。当 Promise 状态为 fulfilled 时，调用 then 的 onfulfilled 方法，当 Promise 状态为 rejected 时，调用 then 的 onrejected 方法， 所以在异步操作的完成和绑定处理方法之间不存在竞争）。

## 方法

**`Promise.all(iterable)`**

这个方法返回一个新的 promise 对象，该 promise 对象在 iterable 参数对象里所有的 promise 对象都成功的时候才会触发成功，一旦有任何一个 iterable 里面的 promise 对象失败则立即触发该 promise 对象的失败。这个新的 promise 对象在触发成功状态以后，会把一个包含 iterable 里所有 promise 返回值的数组作为成功回调的返回值，顺序跟 iterable 的顺序保持一致；如果这个新的 promise 对象触发了失败状态，它会把 iterable 里第一个触发失败的 promise 对象的错误信息作为它的失败错误信息。Promise.all 方法常被用于处理多个 promise 对象的状态集合。

每个 iterable 都处于 fulfilled 或者 rejected 状态才返回

如果 iterable===[]，则返回 undefined

```javascript
Promise.all([ajax1, ajax2, ajax3]).then();
```

**`Promise.race(iterable)`**

当 iterable 参数里的任意一个子 promise 被成功或失败后，父 promise 马上也会用子 promise 的成功返回值或失败详情作为参数调用父 promise 绑定的相应句柄，并返回该 promise 对象。

哪个快就用那个的状态

如果 iterable===[]，则报错

**`Promise.reject(reason)`**

返回一个状态为失败的 Promise 对象，并将给定的失败信息传递给对应的处理方法

**`Promise.resolve(value)`**

返回一个状态由给定 value 决定的 Promise 对象。

如果该值是 thenable(即，带有 then 方法的对象)，返回的 Promise 对象的最终状态由 then 方法执行决定；

否则的话(**`该 value 为空，基本类型或者不带 then 方法的对象`**),返回的 Promise 对象状态为 fulfilled，并且将该 value 传递给对应的 then 方法。

通常而言，如果你不知道一个值是否是 Promise 对象，使用 Promise.resolve(value) 来返回一个 Promise 对象,这样就能将该 value 以 Promise 对象形式使用。

## 创建 Promise

Promise 对象是由关键字 new 及其构造函数来创建的。

该构造函数会把一个叫做“处理器函数”（executor function）的函数作为它的参数。这个“处理器函数”接受两个函数——resolve 和 reject ——作为其参数。

**_一旦创建，则立即执行处理器函数_**

**promise 状态一旦改变则不能再变。**

当异步任务顺利完成且返回结果值时，会调用 resolve 函数；而当异步任务失败且返回失败原因（通常是一个错误对象）时，会调用 reject 函数。

```javascript
const myFirstPromise = new Promise((resolve, reject) => {
  // ?做一些异步操作，最终会调用下面两者之一:
  //
  //   resolve(someValue); // fulfilled
  // ?或
  //   reject("failure reason"); // rejected
});
```

想要某个函数?拥有 promise 功能，只需让其返回一个 promise 即可。

```javascript
function myAsyncFunction(url) {
  return new Promise((resolve, reject) => {
    const xhr = new XMLHttpRequest();
    xhr.open("GET", url);
    xhr.onload = () => resolve(xhr.responseText);
    xhr.onerror = () => reject(xhr.statusText);
    xhr.send();
  });
}
```

## 面试题解析

```javascript
Promise.resolve(1)
  .then(2)
  .then(Promise.resolve(3))
  .then(console.log)

#### 解析

Promise.resolve 方法的参数如果是一个原始值，或者是一个不具有 then 方法的对象，则 Promise.resolve 方法返回一个新的 Promise 对象，状态为resolved，Promise.resolve 方法的参数，会同时传给回调函数。

then 方法接受的参数是函数，而如果传递的并非是一个函数，它实际上会将其解释为 then(null)，这就会导致前一个 Promise 的结果会穿透下面。

上面题目等于： Promise.resolve(1).then(console.log)
```

```javascript
// 涉及eventLoop

const promise1 = new Promise((resolve, reject) => {
  setTimeout(() => {
    resolve("foo");
  }, 300);
});

promise1.then((value) => {
  console.log(value);
  // expected output: "foo"
});

console.log(promise1);
// expected output: [object Promise]
```

<!-- ## await 做了什么

从字面意思上看 await 就是等待，await 等待的是一个表达式，这个表达式的返回值可以是一个 promise 对象也可以是其他值。
很多人以为 await 会一直等待之后的表达式执行完之后才会继续执行后面的代码，实际上 await 是一个让出线程的标志。await 后面的表达式会先执行一遍，将 await 后面的代码加入到 microtask 中，然后就会跳出整个 async 函数来执行后面的代码。
```
async function async1() {
	console.log('async1 start');
	await async2();
	console.log('async1 end');
}
```

```
async function async1() {
	console.log('async1 start');
	Promise.resolve(async2()).then(() => {
                console.log('async1 end');
        })
}
``` -->

```javascript

async function async1(){
   console.log('async1 start');
    await async2();
    console.log('async1 end')
}
async function async2(){
    console.log('async2')
}

console.log('script start');
async1();
console.log('script end')

// 输出顺序：script start->async1 start->async2->script end->async1 end
async 函数返回一个 Promise 对象，当函数执行的时候，一旦遇到 await 就会先返回，等到触发的异步操作完成，再执行函数体内后面的语句。可以理解为，是让出了线程，跳出了 async 函数体。
```

隐式 try…catch

Promise 的执行者（executor）和 promise 的处理程序（handler）周围有一个“隐式的 try..catch”。如果发生异常，它（译注：指异常）就会被捕获，并被视为 rejection 进行处理。

```javascript
new Promise((resolve, reject) => {
  throw new Error("Whoops!");
}).catch(alert); // Error: Whoops!

===

new Promise((resolve, reject) => {
  reject(new Error("Whoops!"));
}).catch(alert); // Error: Whoops!
```

## 注意

async 函数在 await 之前的代码都是同步执行的，可以理解为 await 之前的代码属于 new Promise 时传入的代码，await 之后的所有代码都是在 Promise.then 中的回调

## es6 module 解决前端工程化开发 umd amd commonjs

## 迭代器，生成器，promise,async/await

## 相关阅读

[promise 掘金](https://juejin.im/post/6844904077537574919#heading-3)
